2019-04-12 10:19:18,767 20 config.py [66]: update app.config [: env][env_active] from dev to dev
2019-04-12 10:19:18,866 40 db_mysql.py [58]: get special aggregation data error
Traceback (most recent call last):
  File "D:\NLP Project\comment_extract\db\db_mysql.py", line 52, in loadDictionary
    conn.execute(sql)
  File "D:\Program Files\Python\python35\lib\site-packages\pymysql\cursors.py", line 165, in execute
    result = self._query(query)
  File "D:\Program Files\Python\python35\lib\site-packages\pymysql\cursors.py", line 321, in _query
    conn.query(q)
  File "D:\Program Files\Python\python35\lib\site-packages\pymysql\connections.py", line 860, in query
    self._affected_rows = self._read_query_result(unbuffered=unbuffered)
  File "D:\Program Files\Python\python35\lib\site-packages\pymysql\connections.py", line 1061, in _read_query_result
    result.read()
  File "D:\Program Files\Python\python35\lib\site-packages\pymysql\connections.py", line 1349, in read
    first_packet = self.connection._read_packet()
  File "D:\Program Files\Python\python35\lib\site-packages\pymysql\connections.py", line 1018, in _read_packet
    packet.check_error()
  File "D:\Program Files\Python\python35\lib\site-packages\pymysql\connections.py", line 384, in check_error
    err.raise_mysql_exception(self._data)
  File "D:\Program Files\Python\python35\lib\site-packages\pymysql\err.py", line 107, in raise_mysql_exception
    raise errorclass(errno, errval)
pymysql.err.ProgrammingError: (1146, "Table 'stargazer_business.keyword_dic' doesn't exist")
2019-04-12 10:23:35,377 20 config.py [66]: update app.config [: env][env_active] from dev to dev
2019-04-12 10:23:35,479 40 db_mysql.py [39]: connect mysql failure
Traceback (most recent call last):
  File "D:\Program Files\Python\python35\lib\site-packages\pymysql\connections.py", line 920, in connect
    **kwargs)
  File "D:\Program Files\Python\python35\lib\socket.py", line 694, in create_connection
    for res in getaddrinfo(host, port, 0, SOCK_STREAM):
  File "D:\Program Files\Python\python35\lib\socket.py", line 733, in getaddrinfo
    for res in _socket.getaddrinfo(host, port, family, type, proto, flags):
socket.gaierror: [Errno 11001] getaddrinfo failed

During handling of the above exception, another exception occurred:

Traceback (most recent call last):
  File "D:\NLP Project\comment_extract\db\db_mysql.py", line 37, in getMysqlConnect
    conn = pymysql.connect(host=host, user=username, passwd=password, db=database, port=port, charset=charset ,autocommit=False,cursorclass=pymysql.cursors.Cursor)
  File "D:\Program Files\Python\python35\lib\site-packages\pymysql\__init__.py", line 90, in Connect
    return Connection(*args, **kwargs)
  File "D:\Program Files\Python\python35\lib\site-packages\pymysql\connections.py", line 699, in __init__
    self.connect()
  File "D:\Program Files\Python\python35\lib\site-packages\pymysql\connections.py", line 967, in connect
    raise exc
pymysql.err.OperationalError: (2003, "Can't connect to MySQL server on '172.16.17.115:3306' ([Errno 11001] getaddrinfo failed)")
2019-04-12 10:23:35,489 40 db_mysql.py [58]: get special aggregation data error
Traceback (most recent call last):
  File "D:\NLP Project\comment_extract\db\db_mysql.py", line 50, in loadDictionary
    with getMysqlConnect() as conn:
  File "D:\NLP Project\comment_extract\db\db_mysql.py", line 40, in getMysqlConnect
    return conn
UnboundLocalError: local variable 'conn' referenced before assignment
2019-04-12 10:25:32,651 20 config.py [66]: update app.config [: env][env_active] from dev to dev
2019-04-12 10:25:52,479 40 db_mysql.py [39]: connect mysql failure
Traceback (most recent call last):
  File "D:\Program Files\Python\python35\lib\site-packages\pymysql\connections.py", line 920, in connect
    **kwargs)
  File "D:\Program Files\Python\python35\lib\socket.py", line 694, in create_connection
    for res in getaddrinfo(host, port, 0, SOCK_STREAM):
  File "D:\Program Files\Python\python35\lib\socket.py", line 733, in getaddrinfo
    for res in _socket.getaddrinfo(host, port, family, type, proto, flags):
socket.gaierror: [Errno 11001] getaddrinfo failed

During handling of the above exception, another exception occurred:

Traceback (most recent call last):
  File "D:\NLP Project\comment_extract\db\db_mysql.py", line 37, in getMysqlConnect
    conn = pymysql.connect(host=host, user=username, passwd=password, db=database, port=port, charset=charset ,autocommit=False,cursorclass=pymysql.cursors.Cursor)
  File "D:\Program Files\Python\python35\lib\site-packages\pymysql\__init__.py", line 90, in Connect
    return Connection(*args, **kwargs)
  File "D:\Program Files\Python\python35\lib\site-packages\pymysql\connections.py", line 699, in __init__
    self.connect()
  File "D:\Program Files\Python\python35\lib\site-packages\pymysql\connections.py", line 967, in connect
    raise exc
pymysql.err.OperationalError: (2003, "Can't connect to MySQL server on '172.16.17.115:3306' ([Errno 11001] getaddrinfo failed)")
2019-04-12 10:25:52,499 40 db_mysql.py [58]: get keyword data error
Traceback (most recent call last):
  File "D:\NLP Project\comment_extract\db\db_mysql.py", line 50, in loadDictionary
    with getMysqlConnect() as conn:
  File "D:\NLP Project\comment_extract\db\db_mysql.py", line 40, in getMysqlConnect
    return conn
UnboundLocalError: local variable 'conn' referenced before assignment
2019-04-12 10:26:31,881 20 config.py [66]: update app.config [: env][env_active] from dev to dev
2019-04-12 10:27:11,590 40 db_mysql.py [39]: connect mysql failure
Traceback (most recent call last):
  File "D:\Program Files\Python\python35\lib\site-packages\pymysql\connections.py", line 920, in connect
    **kwargs)
  File "D:\Program Files\Python\python35\lib\socket.py", line 694, in create_connection
    for res in getaddrinfo(host, port, 0, SOCK_STREAM):
  File "D:\Program Files\Python\python35\lib\socket.py", line 733, in getaddrinfo
    for res in _socket.getaddrinfo(host, port, family, type, proto, flags):
socket.gaierror: [Errno 11001] getaddrinfo failed

During handling of the above exception, another exception occurred:

Traceback (most recent call last):
  File "D:\NLP Project\comment_extract\db\db_mysql.py", line 37, in getMysqlConnect
    conn = pymysql.connect(host=host, user=username, passwd=password, db=database, port=port, charset=charset ,autocommit=False,cursorclass=pymysql.cursors.Cursor)
  File "D:\Program Files\Python\python35\lib\site-packages\pymysql\__init__.py", line 90, in Connect
    return Connection(*args, **kwargs)
  File "D:\Program Files\Python\python35\lib\site-packages\pymysql\connections.py", line 699, in __init__
    self.connect()
  File "D:\Program Files\Python\python35\lib\site-packages\pymysql\connections.py", line 967, in connect
    raise exc
pymysql.err.OperationalError: (2003, "Can't connect to MySQL server on '172.16.17.115:3306' ([Errno 11001] getaddrinfo failed)")
2019-04-12 10:27:11,597 40 db_mysql.py [58]: get keyword data error
Traceback (most recent call last):
  File "D:\NLP Project\comment_extract\db\db_mysql.py", line 50, in loadDictionary
    with getMysqlConnect() as conn:
  File "D:\NLP Project\comment_extract\db\db_mysql.py", line 40, in getMysqlConnect
    return conn
UnboundLocalError: local variable 'conn' referenced before assignment
2019-04-12 10:27:45,110 20 config.py [66]: update app.config [: env][env_active] from dev to dev
2019-04-12 10:29:24,321 40 db_mysql.py [39]: connect mysql failure
Traceback (most recent call last):
  File "D:\NLP Project\comment_extract\db\db_mysql.py", line 37, in getMysqlConnect
    conn = pymysql.connect(host=host, user=username, passwd=password, db=database, port=port, charset=charset ,autocommit=False,cursorclass=pymysql.cursors.Cursor)
  File "D:\Program Files\Python\python35\lib\site-packages\pymysql\__init__.py", line 90, in Connect
    return Connection(*args, **kwargs)
  File "D:\Program Files\Python\python35\lib\site-packages\pymysql\connections.py", line 669, in __init__
    self.encoding = charset_by_name(self.charset).encoding
AttributeError: 'NoneType' object has no attribute 'encoding'
2019-04-12 10:29:26,793 40 db_mysql.py [58]: get keyword data error
Traceback (most recent call last):
  File "D:\NLP Project\comment_extract\db\db_mysql.py", line 50, in loadDictionary
    with getMysqlConnect() as conn:
  File "D:\NLP Project\comment_extract\db\db_mysql.py", line 40, in getMysqlConnect
    return conn
UnboundLocalError: local variable 'conn' referenced before assignment
2019-04-12 10:37:33,416 20 config.py [66]: update app.config [: env][env_active] from dev to dev
2019-04-12 10:38:15,535 40 db_mysql.py [39]: connect mysql failure
Traceback (most recent call last):
  File "D:\NLP Project\comment_extract\db\db_mysql.py", line 37, in getMysqlConnect
    conn = pymysql.connect(host=host, user=username, passwd=password, db=database, port=port, charset=charset ,autocommit=False,cursorclass=pymysql.cursors.Cursor)
  File "D:\Program Files\Python\python35\lib\site-packages\pymysql\__init__.py", line 90, in Connect
    return Connection(*args, **kwargs)
  File "D:\Program Files\Python\python35\lib\site-packages\pymysql\connections.py", line 669, in __init__
    self.encoding = charset_by_name(self.charset).encoding
AttributeError: 'NoneType' object has no attribute 'encoding'
2019-04-12 10:38:15,556 40 db_mysql.py [58]: get keyword data error
Traceback (most recent call last):
  File "D:\NLP Project\comment_extract\db\db_mysql.py", line 50, in loadDictionary
    with getMysqlConnect() as conn:
  File "D:\NLP Project\comment_extract\db\db_mysql.py", line 40, in getMysqlConnect
    return conn
UnboundLocalError: local variable 'conn' referenced before assignment
2019-04-12 10:41:14,998 20 config.py [66]: update app.config [: env][env_active] from dev to dev
2019-04-12 10:41:19,981 40 db_mysql.py [39]: connect mysql failure
Traceback (most recent call last):
  File "D:\Program Files\Python\python35\lib\site-packages\pymysql\connections.py", line 920, in connect
    **kwargs)
  File "D:\Program Files\Python\python35\lib\socket.py", line 694, in create_connection
    for res in getaddrinfo(host, port, 0, SOCK_STREAM):
  File "D:\Program Files\Python\python35\lib\socket.py", line 733, in getaddrinfo
    for res in _socket.getaddrinfo(host, port, family, type, proto, flags):
socket.gaierror: [Errno 11001] getaddrinfo failed

During handling of the above exception, another exception occurred:

Traceback (most recent call last):
  File "D:\NLP Project\comment_extract\db\db_mysql.py", line 37, in getMysqlConnect
    conn = pymysql.connect(host=host, user=username, passwd=password, db=database, port=port, charset=charset ,autocommit=False,cursorclass=pymysql.cursors.Cursor)
  File "D:\Program Files\Python\python35\lib\site-packages\pymysql\__init__.py", line 90, in Connect
    return Connection(*args, **kwargs)
  File "D:\Program Files\Python\python35\lib\site-packages\pymysql\connections.py", line 699, in __init__
    self.connect()
  File "D:\Program Files\Python\python35\lib\site-packages\pymysql\connections.py", line 967, in connect
    raise exc
pymysql.err.OperationalError: (2003, "Can't connect to MySQL server on '172.16.17.115:3306' ([Errno 11001] getaddrinfo failed)")
2019-04-12 10:41:20,002 40 db_mysql.py [58]: get keyword data error
Traceback (most recent call last):
  File "D:\NLP Project\comment_extract\db\db_mysql.py", line 50, in loadDictionary
    with getMysqlConnect() as conn:
  File "D:\NLP Project\comment_extract\db\db_mysql.py", line 40, in getMysqlConnect
    return conn
UnboundLocalError: local variable 'conn' referenced before assignment
2019-04-12 10:49:53,764 20 config.py [66]: update app.config [: env][env_active] from dev to dev
2019-04-12 10:51:00,470 20 config.py [66]: update app.config [: env][env_active] from dev to dev
2019-04-12 10:51:32,275 40 db_mysql.py [58]: get keyword data error
Traceback (most recent call last):
  File "D:\NLP Project\comment_extract\db\db_mysql.py", line 52, in loadDictionary
    conn.execute(sql)
  File "D:\Program Files\Python\python35\lib\site-packages\pymysql\cursors.py", line 165, in execute
    result = self._query(query)
  File "D:\Program Files\Python\python35\lib\site-packages\pymysql\cursors.py", line 321, in _query
    conn.query(q)
  File "D:\Program Files\Python\python35\lib\site-packages\pymysql\connections.py", line 860, in query
    self._affected_rows = self._read_query_result(unbuffered=unbuffered)
  File "D:\Program Files\Python\python35\lib\site-packages\pymysql\connections.py", line 1061, in _read_query_result
    result.read()
  File "D:\Program Files\Python\python35\lib\site-packages\pymysql\connections.py", line 1349, in read
    first_packet = self.connection._read_packet()
  File "D:\Program Files\Python\python35\lib\site-packages\pymysql\connections.py", line 1018, in _read_packet
    packet.check_error()
  File "D:\Program Files\Python\python35\lib\site-packages\pymysql\connections.py", line 384, in check_error
    err.raise_mysql_exception(self._data)
  File "D:\Program Files\Python\python35\lib\site-packages\pymysql\err.py", line 107, in raise_mysql_exception
    raise errorclass(errno, errval)
pymysql.err.InternalError: (1054, "Unknown column 'word，freq，tag' in 'field list'")
2019-04-12 10:52:21,002 20 config.py [66]: update app.config [: env][env_active] from dev to dev
2019-04-12 10:55:32,250 20 config.py [66]: update app.config [: env][env_active] from dev to dev
2019-04-12 10:55:50,479 20 config.py [66]: update app.config [: env][env_active] from dev to dev
2019-04-12 10:56:06,525 20 config.py [66]: update app.config [: env][env_active] from dev to dev
2019-04-12 11:04:02,308 20 config.py [66]: update app.config [: env][env_active] from dev to dev
2019-04-12 11:04:02,421 40 db_mysql.py [58]: get keyword data error
Traceback (most recent call last):
  File "D:\NLP Project\comment_extract\db\db_mysql.py", line 56, in loadDictionary
    keywords.append([record[0],record[1],record[2]].join('\t') + ' \n')
AttributeError: 'list' object has no attribute 'join'
2019-04-12 11:05:13,135 20 config.py [66]: update app.config [: env][env_active] from dev to dev
2019-04-12 11:14:48,371 20 config.py [66]: update app.config [: env][env_active] from dev to dev
2019-04-12 11:19:50,574 20 config.py [66]: update app.config [: env][env_active] from dev to dev
2019-04-12 11:20:14,454 20 config.py [66]: update app.config [: env][env_active] from dev to dev
2019-04-12 11:22:39,279 20 config.py [66]: update app.config [: env][env_active] from dev to dev
2019-04-12 11:26:43,231 20 config.py [66]: update app.config [: env][env_active] from dev to dev
2019-04-12 11:28:01,906 20 config.py [66]: update app.config [: env][env_active] from dev to dev
2019-04-12 11:28:33,075 20 config.py [66]: update app.config [: env][env_active] from dev to dev
2019-04-12 11:28:55,268 20 config.py [66]: update app.config [: env][env_active] from dev to dev
2019-04-12 11:29:31,976 20 config.py [66]: update app.config [: env][env_active] from dev to dev
2019-04-12 11:34:43,673 20 config.py [66]: update app.config [: env][env_active] from dev to dev
2019-04-12 11:35:46,784 20 config.py [66]: update app.config [: env][env_active] from dev to dev
2019-04-12 11:36:33,279 20 config.py [66]: update app.config [: env][env_active] from dev to dev
2019-04-12 11:37:00,491 20 config.py [66]: update app.config [: env][env_active] from dev to dev
2019-04-12 11:38:42,726 20 config.py [66]: update app.config [: env][env_active] from dev to dev
2019-04-12 11:39:04,957 20 config.py [66]: update app.config [: env][env_active] from dev to dev
2019-04-12 11:39:48,371 20 config.py [66]: update app.config [: env][env_active] from dev to dev
2019-04-12 13:48:54,850 20 config.py [66]: update app.config [: env][env_active] from dev to dev
2019-04-12 13:54:11,313 20 config.py [66]: update app.config [: env][env_active] from dev to dev
2019-04-12 13:56:46,151 20 config.py [66]: update app.config [: env][env_active] from dev to dev
2019-04-12 13:58:47,623 20 config.py [66]: update app.config [: env][env_active] from dev to dev
2019-04-12 14:05:53,640 20 config.py [66]: update app.config [: env][env_active] from dev to dev
2019-04-12 15:04:59,495 20 config.py [66]: update app.config [: env][env_active] from dev to dev
2019-04-12 15:07:25,798 20 config.py [66]: update app.config [: env][env_active] from dev to dev
2019-04-12 15:09:30,478 20 config.py [66]: update app.config [: env][env_active] from dev to dev
2019-04-12 15:11:37,375 20 config.py [66]: update app.config [: env][env_active] from dev to dev
2019-04-12 15:13:11,384 20 config.py [66]: update app.config [: env][env_active] from dev to dev
2019-04-12 15:25:48,161 20 config.py [66]: update app.config [: env][env_active] from dev to dev
2019-04-12 15:32:56,875 20 config.py [66]: update app.config [: env][env_active] from dev to dev
2019-04-12 15:41:50,283 20 config.py [66]: update app.config [: env][env_active] from dev to dev
2019-04-12 15:54:59,186 20 config.py [66]: update app.config [: env][env_active] from dev to dev
2019-04-12 15:56:32,790 20 config.py [66]: update app.config [: env][env_active] from dev to dev
2019-04-12 15:57:32,348 20 config.py [66]: update app.config [: env][env_active] from dev to dev
2019-04-12 16:00:31,633 20 config.py [66]: update app.config [: env][env_active] from dev to dev
2019-04-12 16:03:13,940 20 config.py [66]: update app.config [: env][env_active] from dev to dev
2019-04-12 16:11:03,126 20 config.py [66]: update app.config [: env][env_active] from dev to dev
2019-04-12 16:22:06,984 20 config.py [66]: update app.config [: env][env_active] from dev to dev
2019-04-12 16:53:43,073 20 config.py [66]: update app.config [: env][env_active] from dev to dev
2019-04-12 16:55:37,206 20 config.py [66]: update app.config [: env][env_active] from dev to dev
2019-04-12 16:57:42,009 20 config.py [66]: update app.config [: env][env_active] from dev to dev
2019-04-12 17:00:03,705 20 config.py [66]: update app.config [: env][env_active] from dev to dev
2019-04-12 17:05:27,758 20 config.py [66]: update app.config [: env][env_active] from dev to dev
2019-04-12 17:19:38,125 20 config.py [66]: update app.config [: env][env_active] from dev to dev
2019-04-12 17:28:19,250 20 config.py [66]: update app.config [: env][env_active] from dev to dev
2019-04-12 17:35:17,733 20 config.py [66]: update app.config [: env][env_active] from dev to dev
2019-04-12 17:39:16,909 20 config.py [66]: update app.config [: env][env_active] from dev to dev
2019-04-12 17:46:11,717 20 config.py [66]: update app.config [: env][env_active] from dev to dev
2019-04-12 17:49:53,123 20 config.py [66]: update app.config [: env][env_active] from dev to dev
2019-04-12 17:53:26,011 20 config.py [66]: update app.config [: env][env_active] from dev to dev
2019-04-12 17:59:12,282 20 config.py [66]: update app.config [: env][env_active] from dev to dev
2019-04-12 18:05:52,462 20 config.py [66]: update app.config [: env][env_active] from dev to dev
2019-04-12 18:16:45,477 20 config.py [66]: update app.config [: env][env_active] from dev to dev
2019-04-12 18:21:22,469 20 config.py [66]: update app.config [: env][env_active] from dev to dev
2019-04-12 18:23:01,362 20 config.py [66]: update app.config [: env][env_active] from dev to dev
2019-04-12 18:44:51,980 20 config.py [66]: update app.config [: env][env_active] from dev to dev
2019-04-12 18:45:17,591 40 db_mysql.py [75]: get keyword data error
Traceback (most recent call last):
  File "D:\NLP Project\comment_extract\db\db_mysql.py", line 71, in saveDataToDb
    num = conn.executemany(sqls)
TypeError: executemany() missing 1 required positional argument: 'args'
2019-04-12 18:48:32,416 20 config.py [66]: update app.config [: env][env_active] from dev to dev
2019-04-12 18:48:37,911 40 db_mysql.py [76]: get keyword data error
Traceback (most recent call last):
  File "D:\NLP Project\comment_extract\db\db_mysql.py", line 72, in saveDataToDb
    num = conn.executemany(sql,)
TypeError: executemany() missing 1 required positional argument: 'args'
2019-04-12 18:49:10,329 20 config.py [66]: update app.config [: env][env_active] from dev to dev
2019-04-12 18:49:16,015 40 db_mysql.py [76]: get keyword data error
Traceback (most recent call last):
  File "D:\NLP Project\comment_extract\db\db_mysql.py", line 72, in saveDataToDb
    num = conn.executemany(sql,data)
  File "D:\Program Files\Python\python35\lib\site-packages\pymysql\cursors.py", line 194, in executemany
    self.rowcount = sum(self.execute(query, arg) for arg in args)
  File "D:\Program Files\Python\python35\lib\site-packages\pymysql\cursors.py", line 194, in <genexpr>
    self.rowcount = sum(self.execute(query, arg) for arg in args)
  File "D:\Program Files\Python\python35\lib\site-packages\pymysql\cursors.py", line 163, in execute
    query = self.mogrify(query, args)
  File "D:\Program Files\Python\python35\lib\site-packages\pymysql\cursors.py", line 142, in mogrify
    query = query % self._escape_args(args, conn)
TypeError: %d format: a number is required, not str
2019-04-12 18:50:53,673 20 config.py [66]: update app.config [: env][env_active] from dev to dev
2019-04-12 18:51:00,981 40 db_mysql.py [76]: get keyword data error
Traceback (most recent call last):
  File "D:\NLP Project\comment_extract\db\db_mysql.py", line 72, in saveDataToDb
    num = conn.executemany(sql,data)
  File "D:\Program Files\Python\python35\lib\site-packages\pymysql\cursors.py", line 194, in executemany
    self.rowcount = sum(self.execute(query, arg) for arg in args)
  File "D:\Program Files\Python\python35\lib\site-packages\pymysql\cursors.py", line 194, in <genexpr>
    self.rowcount = sum(self.execute(query, arg) for arg in args)
  File "D:\Program Files\Python\python35\lib\site-packages\pymysql\cursors.py", line 163, in execute
    query = self.mogrify(query, args)
  File "D:\Program Files\Python\python35\lib\site-packages\pymysql\cursors.py", line 142, in mogrify
    query = query % self._escape_args(args, conn)
TypeError: %d format: a number is required, not str
2019-04-12 18:53:22,032 20 config.py [66]: update app.config [: env][env_active] from dev to dev
2019-04-12 18:53:28,742 40 db_mysql.py [76]: get keyword data error
Traceback (most recent call last):
  File "D:\NLP Project\comment_extract\db\db_mysql.py", line 72, in saveDataToDb
    num = conn.executemany(sql,data)
  File "D:\Program Files\Python\python35\lib\site-packages\pymysql\cursors.py", line 194, in executemany
    self.rowcount = sum(self.execute(query, arg) for arg in args)
  File "D:\Program Files\Python\python35\lib\site-packages\pymysql\cursors.py", line 194, in <genexpr>
    self.rowcount = sum(self.execute(query, arg) for arg in args)
  File "D:\Program Files\Python\python35\lib\site-packages\pymysql\cursors.py", line 163, in execute
    query = self.mogrify(query, args)
  File "D:\Program Files\Python\python35\lib\site-packages\pymysql\cursors.py", line 142, in mogrify
    query = query % self._escape_args(args, conn)
TypeError: %d format: a number is required, not str
2019-04-12 18:54:36,273 20 config.py [66]: update app.config [: env][env_active] from dev to dev
2019-04-12 18:56:20,541 40 db_mysql.py [76]: get keyword data error
Traceback (most recent call last):
  File "D:\NLP Project\comment_extract\db\db_mysql.py", line 72, in saveDataToDb
    num = conn.executemany(sql,data)
  File "D:\Program Files\Python\python35\lib\site-packages\pymysql\cursors.py", line 194, in executemany
    self.rowcount = sum(self.execute(query, arg) for arg in args)
  File "D:\Program Files\Python\python35\lib\site-packages\pymysql\cursors.py", line 194, in <genexpr>
    self.rowcount = sum(self.execute(query, arg) for arg in args)
  File "D:\Program Files\Python\python35\lib\site-packages\pymysql\cursors.py", line 163, in execute
    query = self.mogrify(query, args)
  File "D:\Program Files\Python\python35\lib\site-packages\pymysql\cursors.py", line 142, in mogrify
    query = query % self._escape_args(args, conn)
TypeError: %d format: a number is required, not str
2019-04-12 18:58:21,701 20 config.py [66]: update app.config [: env][env_active] from dev to dev
2019-04-12 18:58:21,712 20 db_mysql.py [63]: 结果为空
2019-04-12 18:59:42,824 20 config.py [66]: update app.config [: env][env_active] from dev to dev
2019-04-12 18:59:42,844 20 db_mysql.py [63]: 结果为空
2019-04-12 19:01:28,829 20 config.py [66]: update app.config [: env][env_active] from dev to dev
2019-04-12 19:01:36,971 40 db_mysql.py [79]: get keyword data error
Traceback (most recent call last):
  File "D:\NLP Project\comment_extract\db\db_mysql.py", line 72, in saveDataToDb
    for keyword, num in result:
TypeError: 'int' object is not iterable
2019-04-12 19:02:43,285 20 config.py [66]: update app.config [: env][env_active] from dev to dev
2019-04-12 19:03:58,164 20 config.py [66]: update app.config [: env][env_active] from dev to dev
2019-04-12 19:06:06,710 20 config.py [66]: update app.config [: env][env_active] from dev to dev
2019-04-12 19:09:27,103 40 db_mysql.py [79]: get keyword data error
Traceback (most recent call last):
  File "D:\NLP Project\comment_extract\db\db_mysql.py", line 75, in saveDataToDb
    num = conn.executemany(sql,data)
  File "D:\Program Files\Python\python35\lib\site-packages\pymysql\cursors.py", line 194, in executemany
    self.rowcount = sum(self.execute(query, arg) for arg in args)
  File "D:\Program Files\Python\python35\lib\site-packages\pymysql\cursors.py", line 194, in <genexpr>
    self.rowcount = sum(self.execute(query, arg) for arg in args)
  File "D:\Program Files\Python\python35\lib\site-packages\pymysql\cursors.py", line 163, in execute
    query = self.mogrify(query, args)
  File "D:\Program Files\Python\python35\lib\site-packages\pymysql\cursors.py", line 142, in mogrify
    query = query % self._escape_args(args, conn)
TypeError: %d format: a number is required, not str
2019-04-12 19:11:12,687 20 config.py [66]: update app.config [: env][env_active] from dev to dev
2019-04-12 19:13:29,501 20 config.py [66]: update app.config [: env][env_active] from dev to dev
2019-04-12 19:15:25,022 40 db_mysql.py [79]: get keyword data error
Traceback (most recent call last):
  File "D:\NLP Project\comment_extract\db\db_mysql.py", line 75, in saveDataToDb
    num = conn.executemany(sql,data)
  File "D:\Program Files\Python\python35\lib\site-packages\pymysql\cursors.py", line 194, in executemany
    self.rowcount = sum(self.execute(query, arg) for arg in args)
  File "D:\Program Files\Python\python35\lib\site-packages\pymysql\cursors.py", line 194, in <genexpr>
    self.rowcount = sum(self.execute(query, arg) for arg in args)
  File "D:\Program Files\Python\python35\lib\site-packages\pymysql\cursors.py", line 163, in execute
    query = self.mogrify(query, args)
  File "D:\Program Files\Python\python35\lib\site-packages\pymysql\cursors.py", line 142, in mogrify
    query = query % self._escape_args(args, conn)
TypeError: %d format: a number is required, not str
2019-04-12 19:16:55,810 20 config.py [66]: update app.config [: env][env_active] from dev to dev
2019-04-12 19:18:12,223 40 db_mysql.py [79]: get keyword data error
Traceback (most recent call last):
  File "D:\NLP Project\comment_extract\db\db_mysql.py", line 75, in saveDataToDb
    num = conn.executemany(sql,data)
  File "D:\Program Files\Python\python35\lib\site-packages\pymysql\cursors.py", line 194, in executemany
    self.rowcount = sum(self.execute(query, arg) for arg in args)
  File "D:\Program Files\Python\python35\lib\site-packages\pymysql\cursors.py", line 194, in <genexpr>
    self.rowcount = sum(self.execute(query, arg) for arg in args)
  File "D:\Program Files\Python\python35\lib\site-packages\pymysql\cursors.py", line 163, in execute
    query = self.mogrify(query, args)
  File "D:\Program Files\Python\python35\lib\site-packages\pymysql\cursors.py", line 142, in mogrify
    query = query % self._escape_args(args, conn)
TypeError: %d format: a number is required, not str
2019-04-12 19:19:56,056 20 config.py [66]: update app.config [: env][env_active] from dev to dev
2019-04-12 19:24:42,849 40 db_mysql.py [79]: get keyword data error
Traceback (most recent call last):
  File "D:\NLP Project\comment_extract\db\db_mysql.py", line 75, in saveDataToDb
    num = conn.executemany(sql,data)
  File "D:\Program Files\Python\python35\lib\site-packages\pymysql\cursors.py", line 194, in executemany
    self.rowcount = sum(self.execute(query, arg) for arg in args)
  File "D:\Program Files\Python\python35\lib\site-packages\pymysql\cursors.py", line 194, in <genexpr>
    self.rowcount = sum(self.execute(query, arg) for arg in args)
  File "D:\Program Files\Python\python35\lib\site-packages\pymysql\cursors.py", line 163, in execute
    query = self.mogrify(query, args)
  File "D:\Program Files\Python\python35\lib\site-packages\pymysql\cursors.py", line 142, in mogrify
    query = query % self._escape_args(args, conn)
TypeError: %d format: a number is required, not str
2019-04-12 19:26:46,029 20 config.py [66]: update app.config [: env][env_active] from dev to dev
2019-04-12 19:28:11,042 40 db_mysql.py [79]: get keyword data error
Traceback (most recent call last):
  File "D:\NLP Project\comment_extract\db\db_mysql.py", line 75, in saveDataToDb
    num = conn.executemany(sql,data)
  File "D:\Program Files\Python\python35\lib\site-packages\pymysql\cursors.py", line 194, in executemany
    self.rowcount = sum(self.execute(query, arg) for arg in args)
  File "D:\Program Files\Python\python35\lib\site-packages\pymysql\cursors.py", line 194, in <genexpr>
    self.rowcount = sum(self.execute(query, arg) for arg in args)
  File "D:\Program Files\Python\python35\lib\site-packages\pymysql\cursors.py", line 165, in execute
    result = self._query(query)
  File "D:\Program Files\Python\python35\lib\site-packages\pymysql\cursors.py", line 321, in _query
    conn.query(q)
  File "D:\Program Files\Python\python35\lib\site-packages\pymysql\connections.py", line 860, in query
    self._affected_rows = self._read_query_result(unbuffered=unbuffered)
  File "D:\Program Files\Python\python35\lib\site-packages\pymysql\connections.py", line 1061, in _read_query_result
    result.read()
  File "D:\Program Files\Python\python35\lib\site-packages\pymysql\connections.py", line 1349, in read
    first_packet = self.connection._read_packet()
  File "D:\Program Files\Python\python35\lib\site-packages\pymysql\connections.py", line 1018, in _read_packet
    packet.check_error()
  File "D:\Program Files\Python\python35\lib\site-packages\pymysql\connections.py", line 384, in check_error
    err.raise_mysql_exception(self._data)
  File "D:\Program Files\Python\python35\lib\site-packages\pymysql\err.py", line 107, in raise_mysql_exception
    raise errorclass(errno, errval)
pymysql.err.InternalError: (1136, "Column count doesn't match value count at row 1")
2019-04-12 19:30:25,814 20 config.py [66]: update app.config [: env][env_active] from dev to dev
2019-04-12 19:34:38,391 20 config.py [66]: update app.config [: env][env_active] from dev to dev
2019-04-12 19:34:38,469 40 db_mysql.py [82]: get keyword data error
Traceback (most recent call last):
  File "D:\NLP Project\comment_extract\db\db_mysql.py", line 78, in saveDataToDb
    num = conn.executemany(sql,data,Date(),Date())
TypeError: Required argument 'year' (pos 1) not found
2019-04-12 19:35:50,529 20 config.py [66]: update app.config [: env][env_active] from dev to dev
2019-04-12 19:35:50,584 40 db_mysql.py [82]: get keyword data error
Traceback (most recent call last):
  File "D:\NLP Project\comment_extract\db\db_mysql.py", line 78, in saveDataToDb
    num = conn.executemany(sql,data,Date(2019,3,23),Date(2019,3,23))
TypeError: executemany() takes 3 positional arguments but 5 were given
2019-04-12 19:37:41,524 20 config.py [66]: update app.config [: env][env_active] from dev to dev
2019-04-12 19:41:31,987 20 config.py [66]: update app.config [: env][env_active] from dev to dev
2019-04-12 19:41:32,060 40 db_mysql.py [81]: get keyword data error
Traceback (most recent call last):
  File "D:\NLP Project\comment_extract\db\db_mysql.py", line 74, in saveDataToDb
    for keyword, num in result:
TypeError: 'int' object is not iterable
2019-04-12 19:42:12,739 20 config.py [66]: update app.config [: env][env_active] from dev to dev
2019-04-12 19:42:49,331 20 config.py [66]: update app.config [: env][env_active] from dev to dev
